2022-04-21 15:41:58,266 INFO    MainThread:22588 [internal.py:wandb_internal():92] W&B internal server running at pid: 22588, started at: 2022-04-21 15:41:58.265619
2022-04-21 15:41:58,268 INFO    WriterThread:22588 [datastore.py:open_for_write():77] open: C:\Users\alexa\Documents\VT Work\2021-2022 Junior Year\2022 Spring\ECE 4424 Machine Learning\Project\yolov5\wandb\run-20220421_154155-3f232asn\run-3f232asn.wandb
2022-04-21 15:41:58,455 DEBUG   SenderThread:22588 [sender.py:send():235] send: header
2022-04-21 15:41:58,455 DEBUG   SenderThread:22588 [sender.py:send():235] send: run
2022-04-21 15:41:58,465 INFO    SenderThread:22588 [sender.py:_maybe_setup_resume():492] checking resume status for None/train/3f232asn
2022-04-21 15:42:05,057 ERROR   SenderThread:22588 [retry.py:__call__():126] Retry attempt failed:
Traceback (most recent call last):
  File "C:\Python39\lib\site-packages\urllib3\connection.py", line 169, in _new_conn
    conn = connection.create_connection(
  File "C:\Python39\lib\site-packages\urllib3\util\connection.py", line 73, in create_connection
    for res in socket.getaddrinfo(host, port, family, socket.SOCK_STREAM):
  File "C:\Python39\lib\socket.py", line 953, in getaddrinfo
    for res in _socket.getaddrinfo(host, port, family, type, proto, flags):
socket.gaierror: [Errno 11001] getaddrinfo failed

During handling of the above exception, another exception occurred:

Traceback (most recent call last):
  File "C:\Python39\lib\site-packages\urllib3\connectionpool.py", line 699, in urlopen
    httplib_response = self._make_request(
  File "C:\Python39\lib\site-packages\urllib3\connectionpool.py", line 382, in _make_request
    self._validate_conn(conn)
  File "C:\Python39\lib\site-packages\urllib3\connectionpool.py", line 1010, in _validate_conn
    conn.connect()
  File "C:\Python39\lib\site-packages\urllib3\connection.py", line 353, in connect
    conn = self._new_conn()
  File "C:\Python39\lib\site-packages\urllib3\connection.py", line 181, in _new_conn
    raise NewConnectionError(
urllib3.exceptions.NewConnectionError: <urllib3.connection.HTTPSConnection object at 0x000002C157464580>: Failed to establish a new connection: [Errno 11001] getaddrinfo failed

During handling of the above exception, another exception occurred:

Traceback (most recent call last):
  File "C:\Python39\lib\site-packages\requests\adapters.py", line 439, in send
    resp = conn.urlopen(
  File "C:\Python39\lib\site-packages\urllib3\connectionpool.py", line 755, in urlopen
    retries = retries.increment(
  File "C:\Python39\lib\site-packages\urllib3\util\retry.py", line 574, in increment
    raise MaxRetryError(_pool, url, error or ResponseError(cause))
urllib3.exceptions.MaxRetryError: HTTPSConnectionPool(host='api.wandb.ai', port=443): Max retries exceeded with url: /graphql (Caused by NewConnectionError('<urllib3.connection.HTTPSConnection object at 0x000002C157464580>: Failed to establish a new connection: [Errno 11001] getaddrinfo failed'))

During handling of the above exception, another exception occurred:

Traceback (most recent call last):
  File "C:\Python39\lib\site-packages\wandb\sdk\lib\retry.py", line 102, in __call__
    result = self._call_fn(*args, **kwargs)
  File "C:\Python39\lib\site-packages\wandb\sdk\internal\internal_api.py", line 141, in execute
    return self.client.execute(*args, **kwargs)
  File "C:\Python39\lib\site-packages\wandb\vendor\gql-0.2.0\wandb_gql\client.py", line 52, in execute
    result = self._get_result(document, *args, **kwargs)
  File "C:\Python39\lib\site-packages\wandb\vendor\gql-0.2.0\wandb_gql\client.py", line 60, in _get_result
    return self.transport.execute(document, *args, **kwargs)
  File "C:\Python39\lib\site-packages\wandb\vendor\gql-0.2.0\wandb_gql\transport\requests.py", line 38, in execute
    request = requests.post(self.url, **post_args)
  File "C:\Python39\lib\site-packages\requests\api.py", line 119, in post
    return request('post', url, data=data, json=json, **kwargs)
  File "C:\Python39\lib\site-packages\requests\api.py", line 61, in request
    return session.request(method=method, url=url, **kwargs)
  File "C:\Python39\lib\site-packages\requests\sessions.py", line 542, in request
    resp = self.send(prep, **send_kwargs)
  File "C:\Python39\lib\site-packages\requests\sessions.py", line 655, in send
    r = adapter.send(request, **kwargs)
  File "C:\Python39\lib\site-packages\requests\adapters.py", line 516, in send
    raise ConnectionError(e, request=request)
requests.exceptions.ConnectionError: HTTPSConnectionPool(host='api.wandb.ai', port=443): Max retries exceeded with url: /graphql (Caused by NewConnectionError('<urllib3.connection.HTTPSConnection object at 0x000002C157464580>: Failed to establish a new connection: [Errno 11001] getaddrinfo failed'))
2022-04-21 15:42:26,243 DEBUG   HandlerThread:22588 [handler.py:handle_request():141] handle_request: shutdown
2022-04-21 15:42:26,243 INFO    HandlerThread:22588 [handler.py:finish():790] shutting down handler
2022-04-21 15:42:26,492 INFO    WriterThread:22588 [datastore.py:close():281] close: C:\Users\alexa\Documents\VT Work\2021-2022 Junior Year\2022 Spring\ECE 4424 Machine Learning\Project\yolov5\wandb\run-20220421_154155-3f232asn\run-3f232asn.wandb
2022-04-21 16:15:16,644 INFO    SenderThread:22588 [dir_watcher.py:__init__():169] watching files in: C:\Users\alexa\Documents\VT Work\2021-2022 Junior Year\2022 Spring\ECE 4424 Machine Learning\Project\yolov5\wandb\run-20220421_154155-3f232asn\files
2022-04-21 16:15:16,644 INFO    SenderThread:22588 [sender.py:_start_run_threads():812] run started: 3f232asn with start time 1650570116
2022-04-21 16:15:16,644 INFO    SenderThread:22588 [sender.py:finish():1107] shutting down sender
2022-04-21 16:15:16,644 INFO    SenderThread:22588 [dir_watcher.py:finish():283] shutting down directory watcher
2022-04-21 16:15:17,655 INFO    SenderThread:22588 [dir_watcher.py:finish():313] scan: C:\Users\alexa\Documents\VT Work\2021-2022 Junior Year\2022 Spring\ECE 4424 Machine Learning\Project\yolov5\wandb\run-20220421_154155-3f232asn\files
2022-04-21 16:15:17,655 INFO    SenderThread:22588 [dir_watcher.py:finish():327] scan save: C:\Users\alexa\Documents\VT Work\2021-2022 Junior Year\2022 Spring\ECE 4424 Machine Learning\Project\yolov5\wandb\run-20220421_154155-3f232asn\files\config.yaml config.yaml
2022-04-21 16:15:17,656 INFO    SenderThread:22588 [file_pusher.py:finish():145] shutting down file pusher
2022-04-21 16:15:17,656 INFO    SenderThread:22588 [file_pusher.py:join():150] waiting for file pusher
2022-04-21 16:15:18,192 INFO    Thread-13 :22588 [upload_job.py:push():137] Uploaded file C:\Users\alexa\Documents\VT Work\2021-2022 Junior Year\2022 Spring\ECE 4424 Machine Learning\Project\yolov5\wandb\run-20220421_154155-3f232asn\files\config.yaml
2022-04-21 16:15:18,862 INFO    MainThread:22588 [internal.py:handle_exit():82] Internal process exited
